<?xml version="1.0" ?>

<robot name="manip">
    
    <link name="fixed_torso">
        <inertial>
            <mass value="1024" />
            <origin rpy="0 0 0" xyz="0 0 0" />
            <inertia ixx="170.6" ixy="0" ixz="0" iyy="170.6" iyz="0" izz="170.6" />
        </inertial>
      <collision>
        <origin rpy="0 0 0" xyz="0 0 0"/>
            <geometry>
                <cylinder radius="0.5" length="1"/>
            </geometry>
      </collision>
        <visual>
            <origin rpy="0 0 0" xyz="0 0 0"/>
            <geometry>
                <cylinder radius="0.5" length="1"/>
            </geometry>
        </visual>
    </link>
    
    <joint name="fixed_torso_to_shoulder" type="revolute">
        <axis xyz="0 0 1" />
        <limit effort="1000.0" lower="-3.14" upper="3.14" velocity="0.5" />
        <origin rpy="0 0 0" xyz="0 0 0.5"/>
        <parent link="fixed_torso"/>
        <child link="shoulder"/>
    </joint>

    <transmission name="trans_fixed_torso_to_shoulder">
      <type>transmission_interface/SimpleTransmission</type>
      <joint name="fixed_torso_to_shoulder">
        <hardwareInterface>hardware_interface/EffortJointInterface</hardwareInterface>
      </joint>
      <actuator name="motor_fixed_torso_to_shoulder">
        <mechanicalReduction>1</mechanicalReduction>
        <hardwareInterface>hardware_interface/EffortJointInterface</hardwareInterface>
      </actuator>
    </transmission>
    
    <link name="shoulder">
        <inertial>
        <mass value="1.0" />
        <origin rpy="0 0 0" xyz="0 0 0.1" />
        <inertia ixx="13.2" ixy="0" ixz="0" iyy="13.2" iyz="0" izz="9.6" />
      </inertial>
      <collision>
        <origin rpy="0 0 0" xyz="0 0 0.1"/>
            <geometry>
                <cylinder radius="0.35" length="0.4"/>
            </geometry>
      </collision>
        <visual>
            <origin rpy="0 0 0" xyz="0 0 0.1"/>
            <geometry>
                <cylinder radius="0.35" length="0.4"/>
            </geometry>
        </visual>
    </link>

    <joint name="shoulder_to_lowerarm" type="revolute">
        <axis xyz="0 1 0" />
        <limit effort="1000.0" lower="-3.14" upper="3.14" velocity="0.5" />
        <origin rpy="0 0 0" xyz="0 0 0.2"/>
        <parent link="shoulder"/>
        <child link="lowerarm"/>
    </joint>

    <transmission name="trans_shoulder_to_lowerarm">
      <type>transmission_interface/SimpleTransmission</type>
      <joint name="shoulder_to_lowerarm">
        <hardwareInterface>hardware_interface/EffortJointInterface</hardwareInterface>
      </joint>
      <actuator name="motor_shoulder_to_lowerarm">
        <mechanicalReduction>1</mechanicalReduction>
        <hardwareInterface>hardware_interface/EffortJointInterface</hardwareInterface>
      </actuator>
    </transmission>
    
    <link name="lowerarm">
        <inertial>
        <mass value="1.0" />
        <origin rpy="0 0 0" xyz="0 0 0.4" />
        <inertia ixx="12.6" ixy="0" ixz="0" iyy="12.6" iyz="0" izz="0.6" />
      </inertial>
      <collision>
        <origin rpy="0 0 0" xyz="0 0 0.4"/>
            <geometry>
                <cylinder radius="0.15" length="0.8"/>
            </geometry>
      </collision>
        <visual>
            <origin rpy="0 0 0" xyz="0 0 0.4"/>
            <geometry>
                <cylinder radius="0.15" length="0.8"/>
            </geometry>
        </visual>
    </link>

    <joint name="lowerarm_to_upperarm" type="revolute">
        <axis xyz="0 1 0" />
        <limit effort="1000.0" lower="-3.14" upper="3.14" velocity="0.5" />
        <origin rpy="0 0 0" xyz="0 0 0.8"/>
        <parent link="lowerarm"/>
        <child link="upperarm"/>
    </joint>

    <transmission name="trans_lowerarm_to_upperarm">
      <type>transmission_interface/SimpleTransmission</type>
      <joint name="lowerarm_to_upperarm">
        <hardwareInterface>hardware_interface/EffortJointInterface</hardwareInterface>
      </joint>
      <actuator name="motor_lowerarm_to_upperarm">
        <mechanicalReduction>1</mechanicalReduction>
        <hardwareInterface>hardware_interface/EffortJointInterface</hardwareInterface>
      </actuator>
    </transmission>
    
    <link name="upperarm">
        <inertial>
        <mass value="1.0" />
        <origin rpy="0 0 0" xyz="0 0 0.4" />
        <inertia ixx="12.6" ixy="0" ixz="0" iyy="12.6" iyz="0" izz="0.6" />
      </inertial>
      <collision>
        <origin rpy="0 0 0" xyz="0 0 0.4"/>
            <geometry>
                <cylinder radius="0.15" length="0.8"/>
            </geometry>
      </collision>
        <visual>
            <origin rpy="0 0 0" xyz="0 0 0.4"/>
            <geometry>
                <cylinder radius="0.15" length="0.8"/>
            </geometry>
        </visual>
    </link>

    <joint name="upperarm_to_wrist" type="revolute">
        <axis xyz="0 1 0" />
        <limit effort="1000.0" lower="-3.14" upper="3.14" velocity="0.5" />
        <origin rpy="0 0 0" xyz="0 0 0.8"/>
        <parent link="upperarm"/>
        <child link="wrist"/>
    </joint>

    <transmission name="trans_upperarm_to_wrist">
      <type>transmission_interface/SimpleTransmission</type>
      <joint name="upperarm_to_wrist">
        <hardwareInterface>hardware_interface/EffortJointInterface</hardwareInterface>
      </joint>
      <actuator name="motor_upperarm_to_wrist">
        <mechanicalReduction>1</mechanicalReduction>
        <hardwareInterface>hardware_interface/EffortJointInterface</hardwareInterface>
      </actuator>
    </transmission>
    
    <link name="wrist">
        <inertial>
        <mass value="1.0" />
        <origin rpy="0 0 0" xyz="0 0 0.4" />
        <inertia ixx="12.6" ixy="0" ixz="0" iyy="12.6" iyz="0" izz="0.6" />
      </inertial>
      <collision>
        <origin rpy="0 0 0" xyz="0 0 0.4"/>
            <geometry>
                <cylinder radius="0.15" length="0.8"/>
            </geometry>
      </collision>
        <visual>
            <origin rpy="0 0 0" xyz="0 0 0.4"/>
            <geometry>
                <cylinder radius="0.15" length="0.8"/>
            </geometry>
        </visual>
    </link>

    <joint name="wrist_to_finger" type="revolute">
        <axis xyz="0 1 0" />
        <limit effort="1000.0" lower="-3.14" upper="3.14" velocity="0.5" />
        <origin rpy="0 0 0" xyz="0 0 0.8"/>
        <parent link="wrist"/>
        <child link="finger"/>
    </joint>

    <transmission name="trans_wrist_to_finger">
      <type>transmission_interface/SimpleTransmission</type>
      <joint name="wrist_to_finger">
        <hardwareInterface>hardware_interface/EffortJointInterface</hardwareInterface>
      </joint>
      <actuator name="motor_wrist_to_finger">
        <mechanicalReduction>1</mechanicalReduction>
        <hardwareInterface>hardware_interface/EffortJointInterface</hardwareInterface>
      </actuator>
    </transmission>
    
    <link name="finger">
        <inertial>
        <mass value="1.0" />
        <origin rpy="0 0 0" xyz="0 0 0.125" />
        <inertia ixx="0.4" ixy="0" ixz="0" iyy="0.4" iyz="0" izz="0.2" />
      </inertial>
      <collision>
        <origin rpy="0 0 0" xyz="0 0 0.125"/>
            <geometry>
                <cylinder radius="0.15" length="0.25"/>
            </geometry>
      </collision>
        <visual>
            <origin rpy="0 0 0" xyz="0 0 0.125"/>
            <geometry>
                <cylinder radius="0.15" length="0.25"/>
            </geometry>
        </visual>
    </link>

<gazebo>
    <plugin name="gazebo_ros_control" filename="libgazebo_ros_control.so">
    </plugin>
  </gazebo>

</robot>
